Workbook
Name nom_société: #REF!
Name LigneTitreRégion1..C7: #REF!
Name LigneTitreRégion2..G5: #REF!
Name LigneTitreRégion3..G26: #REF!

Sheet Suivi Client
B1: Prénom | C1: Nom Complet | D1: Mail | E1: Adresse | F1: Code Postale | G1: Ville | H1: Numéro de téléphone
A2: Carouge | B2: Léo | C2: ='Suivi Client'!$B2 & " " &'Suivi Client'!$A2 -> Léo Carouge | D2: leocarouge@gmail.com | E2: 144 Avenue de Flandre | F2: 75019 | G2: PARIS | H2: 645080351
A3: marrié | B3: Agnès | C3: ='Suivi Client'!$B3 & " " &'Suivi Client'!$A3 -> Agnès marrié
A4: leclézio | B4: Pierre | C4: ='Suivi Client'!$B4 & " " &'Suivi Client'!$A4 -> Pierre leclézio | F4: 75016 | G4: PARIS
A5: LAPEDAGNE | B5: GAEL | C5: ='Suivi Client'!$B5 & " " &'Suivi Client'!$A5 -> GAEL LAPEDAGNE | G5: SAINT JEAN DE LUZ
A6: MADARIAGA | B6: OIHAN | C6: ='Suivi Client'!$B6 & " " &'Suivi Client'!$A6 -> OIHAN MADARIAGA | G6: HENDAYE
A7: WOJTOWIC | B7: ACHILLE | C7: ='Suivi Client'!$B7 & " " &'Suivi Client'!$A7 -> ACHILLE WOJTOWIC | G7: SAINT JEAN DE LUZ
A8: LASSERRE | B8: BASTIEN | C8: ='Suivi Client'!$B8 & " " &'Suivi Client'!$A8 -> BASTIEN LASSERRE | G8: CIBOUR
A9: LANDRIEU | B9: HUGO | C9: ='Suivi Client'!$B9 & " " &'Suivi Client'!$A9 -> HUGO LANDRIEU | G9: SAINT JEAN DE LUZ
A10: COUDRET | B10: CHARLOTTE | C10: ='Suivi Client'!$B10 & " " &'Suivi Client'!$A10 -> CHARLOTTE COUDRET | G10: SAINT JEAN DE LUZ
A11: BILBAO | B11: XANTI | C11: ='Suivi Client'!$B11 & " " &'Suivi Client'!$A11 -> XANTI BILBAO | G11: CIBOUR
A12: POULHES | B12: CHARLES | C12: ='Suivi Client'!$B12 & " " &'Suivi Client'!$A12 -> CHARLES POULHES | F12: 75019 | G12: PARIS
A13: SIMON | B13: ALEXANDRE | C13: ='Suivi Client'!$B13 & " " &'Suivi Client'!$A13 -> ALEXANDRE SIMON | F13: 75020 | G13: PARIS
A14: ETXABE | B14: GENTZA | C14: ='Suivi Client'!$B14 & " " &'Suivi Client'!$A14 -> GENTZA ETXABE | G14: URRUGNE
A15: COTINA | B15: BIXENTE | C15: ='Suivi Client'!$B15 & " " &'Suivi Client'!$A15 -> BIXENTE COTINA | G15: URRUGNE
A16: AIZPURUA | B16: GABI | C16: ='Suivi Client'!$B16 & " " &'Suivi Client'!$A16 -> GABI AIZPURUA | G16: HENDAYE
A17: MATESANZE | B17: JAIME | C17: ='Suivi Client'!$B17 & " " &'Suivi Client'!$A17 -> JAIME MATESANZE | G17: HENDAYE
A18: DUBARBIER | B18: JOELLE | C18: ='Suivi Client'!$B18 & " " &'Suivi Client'!$A18 -> JOELLE DUBARBIER | G18: SAINT JEAN DE LUZ
A19: Cireddu | B19: Gregory | C19: ='Suivi Client'!$B19 & " " &'Suivi Client'!$A19 -> Gregory Cireddu | F19: 57 | G19: Mazeroy
A20: Gintrand | B20: Philippe | C20: ='Suivi Client'!$B20 & " " &'Suivi Client'!$A20 -> Philippe Gintrand | E20: 2 CHEMIN D OLLANET | F20: 26240 | G20: St vallier
A21: Fassaert | B21: Pascal | C21: ='Suivi Client'!$B21 & " " &'Suivi Client'!$A21 -> Pascal Fassaert | E21: ROUTE DE PLANCY | F21: 10170 | G21: Mery/Seine
A22: Soulhac | B22: Eric | C22: ='Suivi Client'!$B22 & " " &'Suivi Client'!$A22 -> Eric Soulhac | E22: 6 ALLLEE DES TERRASSES DU RHONE | F22: 26140 | G22: St vallier
A23: Bouilot | B23: Jac/dan | C23: ='Suivi Client'!$B23 & " " &'Suivi Client'!$A23 -> Jac/dan Bouilot | E23: 11 RUE LUCIE AUBRAC | F23: 26240 | G23: St vallier
A24: Gintrand | C24: ='Suivi Client'!$B24 & " " &'Suivi Client'!$A24 -> Gintrand | G24: Nimes
A25: Xantie | C25: ='Suivi Client'!$B25 & " " &'Suivi Client'!$A25 -> Xantie | G25: St jean de luz
A26: Morel | B26: Jacques | C26: ='Suivi Client'!$B26 & " " &'Suivi Client'!$A26 -> Jacques Morel | E26: 20 RUE DU 11 NOVEMBRE | F26: 10300 | G26: ST E SAVINE
A27: Jeff | B27: Fassaert | C27: ='Suivi Client'!$B27 & " " &'Suivi Client'!$A27 -> Fassaert Jeff | G27: concarneau
A28: Fassaert | B28: ZACHARIE | C28: ='Suivi Client'!$B28 & " " &'Suivi Client'!$A28 -> ZACHARIE Fassaert | G28: PARIS
A29: FISHER | B29: LEO | C29: ='Suivi Client'!$B29 & " " &'Suivi Client'!$A29 -> LEO FISHER | G29: PARIS
A30: camille | B30: cireddu | C30: ='Suivi Client'!$B30 & " " &'Suivi Client'!$A30 -> cireddu camille | G30: bordeaux
A31: Jean-Louis | B31: Dubois | C31: ='Suivi Client'!$B31 & " " &'Suivi Client'!$A31 -> Dubois Jean-Louis | D31: Jeanlouisdubois@aol.com | E31: 2 impasse le grand fin | F31: 21110 | G31: Torey en plaine
A32: Chataigner | B32: Aymeric | C32: ='Suivi Client'!$B32 & " " &'Suivi Client'!$A32 -> Aymeric Chataigner | G32: Talence
A33: Meon | B33: Benoit | C33: ='Suivi Client'!$B33 & " " &'Suivi Client'!$A33 -> Benoit Meon | D33: b.meon@acofi.com | G33: PARIS
A34: Valerie | B34: Carouge | C34: ='Suivi Client'!$B34 & " " &'Suivi Client'!$A34 -> Carouge Valerie | E34: RUE DE VERDUN | G34: EPERNAY
A35: Carouge | B35: Nino | C35: ='Suivi Client'!$B35 & " " &'Suivi Client'!$A35 -> Nino Carouge | G35: flavigny
A36: jaunet | B36: cedric | C36: ='Suivi Client'!$B36 & " " &'Suivi Client'!$A36 -> cedric jaunet | G36: emmerainville
C37: ='Suivi Client'!$B37 & " " &'Suivi Client'!$A37
A38: Ville | B38: Pascal | C38: ='Suivi Client'!$B38 & " " &'Suivi Client'!$A38 -> Pascal Ville | G38: TROYES
A39: Fassaert | B39: MICHELLE | C39: ='Suivi Client'!$B39 & " " &'Suivi Client'!$A39 -> MICHELLE Fassaert | G39: MERY SUR SEINE
A40: MARTIN | B40: JEAN | C40: ='Suivi Client'!$B40 & " " &'Suivi Client'!$A40 -> JEAN MARTIN | F40: 75019 | G40: PARIS
...

Sheet Feuille 68

Sheet Suivi Facturation 2025
A1: N?8M | B1: Nom Client | C1: NB Selection | D1: NB Rosé | E1: Nb blanc de blan | F1: Nb Prestige | G1: Magnum Selection | I1: Montant TTC bouteilles | J1: Montant HT | K1: Date de facturation | L1: Etat paiement | M1: Etat Commande | N1: paiement | O1: commentaire | P1: Prix Transport TTC | R1: Statistiques | S1: Prix unitaire TTC | T1: =S2/1.2 -> 14.166667
A2: 1 | B2: Léo Carouge | C2: 0 | I2: =IF(L2="Cadeau",0,C2*$S$2+D2*$S$3+E2*$S$4+F2*$S$5+G2*$S$6) -> 0 | J2: =I2/1.2 -> 0 | R2: Sélection | S2: 17
A3: 2 | B3: James Carouge | C3: 8 | E3: 2 | F3: 4 | I3: =IF(L3="Cadeau",0,C3*$S$2+D3*$S$3+E3*$S$4+F3*$S$5+G3*$S$6) -> 0 | J3: =I3/1.2 -> 0 | K3: 45715 | L3: Cadeau | M3: Livrer | N3: CONSO | R3: Rosé | S3: 19
A4: 3 | B4: James Carouge | D4: 2 | F4: 2 | I4: =IF(L4="Cadeau",0,C4*$S$2+D4*$S$3+E4*$S$4+F4*$S$5+G4*$S$6) -> 0 | J4: =I4/1.2 -> 0 | K4: 45725 | L4: Cadeau | M4: Livrer | N4: CONSO | R4: Blanc de blanc | S4: 18.5
A5: 4 | B5: James Carouge | C5: 1 | D5: 1 | E5: 2 | F5: 1 | I5: =IF(L5="Cadeau",0,C5*$S$2+D5*$S$3+E5*$S$4+F5*$S$5+G5*$S$6) -> 0 | J5: =I5/1.2 -> 0 | K5: 45732 | L5: Cadeau | M5: Livrer | N5: CONSO SARDAIGNE | R5: Prestige | S5: 27
A6: 5 | B6: CHRISTINE ABRY | E6: 24 | I6: =IF(L6="Cadeau",0,C6*$S$2+D6*$S$3+E6*$S$4+F6*$S$5+G6*$S$6) -> 444 | J6: =I6/1.2 -> 370 | K6: 45739 | L6: Payé | M6: Livrer | N6: LIVRASON | R6: Magnum Brut Selection | S6: 36
A7: 6 | B7: Aymeric Chataigner | C7: 12 | I7: =IF(L7="Cadeau",0,C7*$S$2+D7*$S$3+E7*$S$4+F7*$S$5+G7*$S$6) -> 204 | J7: =I7/1.2 -> 170 | K7: 45748 | L7: Payé | M7: Livrer | R7: Nb bouteilles vendues | S7: =SUM(C2:D1201) -> 759
A8: 7 | B8: MARC WEBER | E8: 18 | I8: =IF(L8="Cadeau",0,C8*$S$2+D8*$S$3+E8*$S$4+F8*$S$5+G8*$S$6) -> 333 | J8: =I8/1.2 -> 277.5 | K8: 45750 | L8: Payé | M8: Livrer | N8: LIVRAISON
A9: 8 | B9: James Carouge | C9: 1 | D9: 1 | E9: 2 | F9: 3 | I9: =IF(L9="Cadeau",0,C9*$S$2+D9*$S$3+E9*$S$4+F9*$S$5+G9*$S$6) -> 0 | J9: =I9/1.2 -> 0 | K9: 45748 | L9: Cadeau | M9: Livrer | N9: ANN SILVANO ET SARDAIGNE | R9: Chiffre d'affaire | S9: =SUM(I2:I1216) -> 20674.5
A10: 9 | B10: THOMAS BANGRATZ | C10: 36 | E10: 18 | I10: =IF(L10="Cadeau",0,C10*$S$2+D10*$S$3+E10*$S$4+F10*$S$5+G10*$S$6) -> 945 | J10: =I10/1.2 -> 787.5 | K10: 45752 | L10: Payé | M10: Livrer | N10: COLLEGUE LEO VIREMENT
A11: 10 | B11: PHILIPPE NOYARD | E11: 30 | I11: =IF(L11="Cadeau",0,C11*$S$2+D11*$S$3+E11*$S$4+F11*$S$5+G11*$S$6) -> 555 | J11: =I11/1.2 -> 462.5 | K11: 45788 | L11: Payé | M11: A habiller | N11: MARIAGE CADO 1 ROSE
A12: 11 | B12: Jacques Girard | C12: 12 | E12: 12 | I12: =IF(L12="Cadeau",0,C12*$S$2+D12*$S$3+E12*$S$4+F12*$S$5+G12*$S$6) -> 426 | J12: =I12/1.2 -> 355 | K12: 45783 | L12: Payé | M12: Livrer | N12: TRANSPORTER GINTRAND
A13: 12 | I13: =IF(L13="Cadeau",0,C13*$S$2+D13*$S$3+E13*$S$4+F13*$S$5+G13*$S$6) -> 0 | J13: =I13/1.2 -> 0
A14: 35 | B14: Philippe Gintrand | E14: 12 | I14: =IF(L14="Cadeau",0,C14*$S$2+D14*$S$3+E14*$S$4+F14*$S$5+G14*$S$6) -> 222 | J14: =I14/1.2 -> 185 | K14: 45783 | L14: En attente de paiement | N14: DEPOT
A15: 14 | B15: Regis Paquin | E15: 6 | I15: =IF(L15="Cadeau",0,C15*$S$2+D15*$S$3+E15*$S$4+F15*$S$5+G15*$S$6) -> 111 | J15: =I15/1.2 -> 92.5 | K15: 45788 | L15: Payé
A16: 15 | B16: CHRISTINE ABRY | C16: 24 | I16: =IF(L16="Cadeau",0,C16*$S$2+D16*$S$3+E16*$S$4+F16*$S$5+G16*$S$6) -> 408 | J16: =I16/1.2 -> 340 | K16: 45810 | L16: Payé | N16: TRANSPORT GRATUIT
A17: 16 | B17: VICTOIRE SCHMITT | C17: 132 | I17: =IF(L17="Cadeau",0,C17*$S$2+D17*$S$3+E17*$S$4+F17*$S$5+G17*$S$6) -> 2244 | J17: =I17/1.2 -> 1870 | K17: 45820 | L17: Payé | M17: Habillé | N17: TRANPORT GRATUIT VIREMENT
A18: 17 | B18: CAMILLE BELLON | C18: 18 | G18: 3 | I18: =IF(L18="Cadeau",0,C18*$S$2+D18*$S$3+E18*$S$4+F18*$S$5+G18*$S$6) -> 414 | J18: =I18/1.2 -> 345 | K18: 6696903 | L18: Payé | M18: A habiller | N18: MARIAGE CAP FERET
A19: 18 | B19: Léo Carouge | E19: 6 | I19: =IF(L19="Cadeau",0,C19*$S$2+D19*$S$3+E19*$S$4+F19*$S$5+G19*$S$6) -> 0 | J19: =I19/1.2 -> 0 | K19: 45819 | L19: Cadeau | N19: CADEAU
A20: 19 | B20: Nino Carouge | C20: 1 | F20: 1 | I20: =IF(L20="Cadeau",0,C20*$S$2+D20*$S$3+E20*$S$4+F20*$S$5+G20*$S$6) -> 0 | J20: =I20/1.2 -> 0 | K20: 45819 | L20: Cadeau
A21: 20 | B21: James Carouge | D21: 1 | E21: 4 | F21: 1 | I21: =IF(L21="Cadeau",0,C21*$S$2+D21*$S$3+E21*$S$4+F21*$S$5+G21*$S$6) -> 0 | J21: =I21/1.2 -> 0 | K21: 45810 | L21: Cadeau | N21: MEMERE SARDAIGNE
A22: 21 | B22: Philémon Parent | C22: 6 | I22: =IF(L22="Cadeau",0,C22*$S$2+D22*$S$3+E22*$S$4+F22*$S$5+G22*$S$6) -> 102 | J22: =I22/1.2 -> 85 | K22: 45822 | L22: Payé | M22: Livrer | N22: ESPECE
A23: 22 | B23: AIRBNB | C23: 1 | I23: =IF(L23="Cadeau",0,C23*$S$2+D23*$S$3+E23*$S$4+F23*$S$5+G23*$S$6) -> 0 | J23: =I23/1.2 -> 0 | K23: 45826 | L23: Cadeau
A24: 24 | B24: DANIEL ACRES | C24: 12 | I24: =IF(L24="Cadeau",0,C24*$S$2+D24*$S$3+E24*$S$4+F24*$S$5+G24*$S$6) -> 204 | J24: =I24/1.2 -> 170 | K24: 45831 | L24: Payé | N24: ESPECE
A25: 25 | B25: AIRBNB | C25: 1 | I25: =IF(L25="Cadeau",0,C25*$S$2+D25*$S$3+E25*$S$4+F25*$S$5+G25*$S$6) -> 0 | J25: =I25/1.2 -> 0 | K25: 45845 | L25: Cadeau
A26: 26 | B26: Nino Carouge | E26: 1 | I26: =IF(L26="Cadeau",0,C26*$S$2+D26*$S$3+E26*$S$4+F26*$S$5+G26*$S$6) -> 18.5 | J26: =I26/1.2 -> 15.416667 | K26: 45845 | L26: Payé | N26: ESPECE | O26: ESPECE
A27: 27 | B27: CAMILLE BELLON | C27: 72 | G27: 15 | I27: =IF(L27="Cadeau",0,C27*$S$2+D27*$S$3+E27*$S$4+F27*$S$5+G27*$S$6) -> 1764 | J27: =I27/1.2 -> 1470 | K27: 45845 | L27: Payé | N27: BORDEAUX TRANP GRATUIT
A28: 28 | B28: CHRISTINE ABRY | C28: 12 | I28: =IF(L28="Cadeau",0,C28*$S$2+D28*$S$3+E28*$S$4+F28*$S$5+G28*$S$6) -> 204 | J28: =I28/1.2 -> 170 | K28: 45874 | L28: Payé | N28: VIREMENT
A29: 29
A30: 30 | I30: =IF(L30="Cadeau",0,C30*$S$2+D30*$S$3+E30*$S$4+F30*$S$5+G30*$S$6) -> 0 | J30: =I30/1.2 -> 0
A31: 31 | B31: Philippe Gintrand | E31: 12 | I31: =IF(L31="Cadeau",0,C31*$S$2+D31*$S$3+E31*$S$4+F31*$S$5+G31*$S$6) -> 222 | J31: =I31/1.2 -> 185 | K31: 45879 | L31: Payé
A32: 32 | B32: Jac/dan Bouilot | D32: 12 | I32: =IF(L32="Cadeau",0,C32*$S$2+D32*$S$3+E32*$S$4+F32*$S$5+G32*$S$6) -> 228 | J32: =I32/1.2 -> 190 | K32: 45879 | L32: Payé | M32: Livrer | N32: VIREMENT
A33: 33 | B33: James Carouge | C33: 18 | D33: 6 | E33: 12 | F33: 6 | G33: 2 | I33: =IF(L33="Cadeau",0,C33*$S$2+D33*$S$3+E33*$S$4+F33*$S$5+G33*$S$6) -> 0 | J33: =I33/1.2 -> 0 | K33: 45879 | L33: Cadeau | N33: DEPOT SARDAIGNE | O33: DEPOT SARDAIGNE
A34: 34 | B34: SEVERINE PAQUIN | E34: 18 | I34: =IF(L34="Cadeau",0,C34*$S$2+D34*$S$3+E34*$S$4+F34*$S$5+G34*$S$6) -> 333 | J34: =I34/1.2 -> 277.5 | K34: 45901 | L34: Payé | M34: Livrer
A35: 35 | B35: James Carouge | E35: 3 | I35: =IF(L35="Cadeau",0,C35*$S$2+D35*$S$3+E35*$S$4+F35*$S$5+G35*$S$6) -> 0 | J35: =I35/1.2 -> 0 | K35: 45901 | L35: Cadeau | N35: SEVERINE 3 BLC DE BLCS
A36: 36 | B36: James Carouge | C36: 9 | E36: 3 | F36: 2 | I36: =IF(L36="Cadeau",0,C36*$S$2+D36*$S$3+E36*$S$4+F36*$S$5+G36*$S$6) -> 0 | J36: =I36/1.2 -> 0 | K36: 45901 | L36: Cadeau | N36: VENDANGEURS
A37: 37 | B37: PAOLA ZICCA | C37: 6 | D37: 6 | E37: 24 | I37: =IF(L37="Cadeau",0,C37*$S$2+D37*$S$3+E37*$S$4+F37*$S$5+G37*$S$6) -> 660 | J37: =I37/1.2 -> 550 | K37: 45884 | L37: Payé | N37: ESPECE/ITALIE
A38: 38 | B38: SERGIO ZICCA | C38: 6 | I38: =IF(L38="Cadeau",0,C38*$S$2+D38*$S$3+E38*$S$4+F38*$S$5+G38*$S$6) -> 102 | J38: =I38/1.2 -> 85 | K38: 45894 | L38: Payé | N38: ESPECE/ ITALIE
A39: 39 | B39: THOMAS BANGRATZ | C39: 84 | I39: =IF(L39="Cadeau",0,C39*$S$2+D39*$S$3+E39*$S$4+F39*$S$5+G39*$S$6) -> 1428 | J39: =I39/1.2 -> 1190 | K39: 45905 | L39: Payé | N39: VIREMENT
A40: 40 | B40: CHRISTINE ABRY | E40: 12 | I40: =IF(L40="Cadeau",0,C40*$S$2+D40*$S$3+E40*$S$4+F40*$S$5+G40*$S$6) -> 222 | J40: =I40/1.2 -> 185 | K40: 45907 | L40: Payé | N40: VIREMENT
...

Sheet Facturation 2025
E5: CHAMPAGNE CAROUGE CIREDDU
C7: S
G8: Nom | I8: =VLOOKUP(C16,'Suivi Facturation 2025'!$A$1:$K$10002,2,FALSE) -> Paul Briest
G9: Adresse | I9: =VLOOKUP(I8,'Suivi Client'!C2:H2960,3,FALSE) -> 2 RUE ST REMY
I10: =VLOOKUP(I8,'Suivi Client'!C2:H2960,4,FALSE) -> 51150 | J10: =VLOOKUP(I8,'Suivi Client'!C2:H2960,5,FALSE) -> Athis
G12: Adresse e-mail | I12: =IF(VLOOKUP(I8,'Suivi Client'!$C$2:$H$2000,2,FALSE)=0,"",VLOOKUP(I8,'Suivi Client'!$C$2:$H$2000,2,FALSE)) -> paul.briestcastaldo@gmail.com
M14: 23
C16: 66
A17: Date de facturation | C17: 46065
A21: Contenance | B21: Designation | H21: Qté | I21: Prix unitaire TTC | K21: Montant TTC
A23: =IF(VLOOKUP($C$16,'Suivi Facturation 2025'!$A$2:$M$1096,3,FALSE)>0,"0,75","") -> 0,75 | B23: =IF(VLOOKUP($C$16,'Suivi Facturation 2025'!$A$2:$M$978,3,FALSE)>0,"Bouteille CHAMPAGNE SELECTION","") -> Bouteille CHAMPAGNE SELECTION | H23: =IF(VLOOKUP($C$16,'Suivi Facturation 2025'!$A$2:$M$1096,3,FALSE)>0,VLOOKUP($C$16,'Suivi Facturation 2025'!$A$2:$M$1096,3,FALSE),"") -> 24 | I23: =IF(VLOOKUP($C$16,'Suivi Facturation 2025'!$A$2:$M$1096,3,FALSE)>0,'Suivi Facturation 2025'!S2,"") -> 17 | K23: =IF(VLOOKUP($C$16,'Suivi Facturation 2025'!$A$2:$M$1096,3,FALSE)>0,I23*H23,"") -> 408
A24: =IF(VLOOKUP($C$16,'Suivi Facturation 2025'!$A$2:$M$1096,4,FALSE)>0,"0,75","") | B24: =IF(VLOOKUP($C$16,'Suivi Facturation 2025'!$A$2:$M$978,4,FALSE)>0,"Bouteille CHAMPAGNE ROSE","") | H24: =IF(VLOOKUP($C$16,'Suivi Facturation 2025'!$A$2:$M$1096,4,FALSE)>0,VLOOKUP($C$16,'Suivi Facturation 2025'!$A$2:$M$1096,4,FALSE),"") | I24: =IF(VLOOKUP($C$16,'Suivi Facturation 2025'!$A$2:$M$1096,4,FALSE)>0,'Suivi Facturation 2025'!S3,"") | K24: =IF(VLOOKUP($C$16,'Suivi Facturation 2025'!$A$2:$M$1096,4,FALSE)>0,I24*H24,"")
A25: =IF(VLOOKUP($C$16,'Suivi Facturation 2025'!$A$2:$M$1096,5,FALSE)>0,"0,75","") -> 0,75 | B25: =IF(VLOOKUP($C$16,'Suivi Facturation 2025'!$A$2:$M$978,5,FALSE)>0,"Bouteille CHAMPAGNE BLANC DE BLANC","") -> Bouteille CHAMPAGNE BLANC DE BLANC | H25: =IF(VLOOKUP($C$16,'Suivi Facturation 2025'!$A$2:$M$1996,5,FALSE)>0,VLOOKUP($C$16,'Suivi Facturation 2025'!$A$2:$M$1996,5,FALSE),"") -> 18 | I25: =IF(VLOOKUP($C$16,'Suivi Facturation 2025'!$A$2:$M$1096,5,FALSE)>0,'Suivi Facturation 2025'!S4,"") -> 18.5 | K25: =IF(VLOOKUP($C$16,'Suivi Facturation 2025'!$A$2:$M$1096,5,FALSE)>0,I25*H25,"") -> 333
A26: =IF(VLOOKUP($C$16,'Suivi Facturation 2025'!$A$2:$M$1096,6,FALSE)>0,"0,75","") | B26: =IF(VLOOKUP($C$16,'Suivi Facturation 2025'!$A$2:$M$1096,6,FALSE)>0,"Bouteille CHAMPAGNE PRESTIGE","") | H26: =IF(VLOOKUP($C$16,'Suivi Facturation 2025'!$A$2:$M$1096,6,FALSE)>0,VLOOKUP($C$16,'Suivi Facturation 2025'!$A$2:$M$1096,6,FALSE),"") | I26: =IF(VLOOKUP($C$16,'Suivi Facturation 2025'!$A$2:$M$1096,6,FALSE)>0,'Suivi Facturation 2025'!S5,"") | K26: =IF(VLOOKUP($C$16,'Suivi Facturation 2025'!$A$2:$M$1096,6,FALSE)>0,I26*H26,"")
A27: =IF(VLOOKUP($C$16,'Suivi Facturation 2025'!$A$2:$M$1096,7,FALSE)>0,"1,5","") | B27: =IF(VLOOKUP($C$16,'Suivi Facturation 2025'!$A$2:$M$1096,7,FALSE)>0,"MAGNUM SELECTION","") | H27: =IF(VLOOKUP($C$16,'Suivi Facturation 2025'!$A$2:$M$1096,7,FALSE)>0,VLOOKUP($C$16,'Suivi Facturation 2025'!$A$2:$M$1096,7,FALSE),"") | I27: =IF(VLOOKUP($C$16,'Suivi Facturation 2025'!$A$2:$M$1096,7,FALSE)>0,'Suivi Facturation 2025'!S6,"") | K27: =IF(VLOOKUP($C$16,'Suivi Facturation 2025'!$A$2:$M$1096,7,FALSE)>0,I27*H27,"")
B28: =IF(VLOOKUP($C$16,'Suivi Facturation 2025'!$A$2:$P$1978,16,FALSE)>0,"PRIX LIVRAISON","") | K28: =IF(VLOOKUP($C$16,'Suivi Facturation 2025'!$A$2:$P$1978,16,FALSE)>0,VLOOKUP($C$16,'Suivi Facturation 2025'!$A$2:$P$1978,16,FALSE),"")
K37: Total HT | L37: =SUM(K23:L30)-L38 -> 617.5
K38: TVA (20%) | L38: =IFERROR(SUM(K23:L29)-SUM(K23:L29)/1.2,"") -> 123.5
K40: Total TTC | L40: =SUM(K23:L30) -> 741
A42: Toute somme impayée à son échéance produira, de plein droit et sans mise en demeure, un intérêt égal à 1,5 fois le taux d'intérêt légal par mois de retard. Nos conditions de vente ne prévoient pas d'escompte pour paiement anticipé. Coordonnées bancaires Titulaire du compte : JAMES CAROUGE IBAN FR76 1020 6000 4848 3510 3712 067 BIC AGRIFRPP802
A54: CHAMPAGNE CAROUGE CIREDDU 6 rue de l'eglise 51190 FLAVIGNY Tel : 06 77 95 90 62 SIRET 843 516 642 00017 N° TVA intracommunautaire FR67 843 516 642

Sheet Facturation 2025 HT
E5: CHAMPAGNE CAROUGE CIREDDU
G8: Nom | I8: =VLOOKUP(C16,'Suivi Facturation 2025'!$A$1:$K$10002,2,FALSE) -> DANIEL ACRES
G9: Adresse | I9: =VLOOKUP(I8,'Suivi Client'!C2:H2960,3,FALSE) -> 16 VIA POGGIARDELLI
I10: =VLOOKUP(I8,'Suivi Client'!C2:H2960,4,FALSE) -> 53045 | J10: =VLOOKUP(I8,'Suivi Client'!C2:H2960,5,FALSE) -> MONTEOULCIANO
G12: Adresse e-mail | I12: =IF(VLOOKUP(I8,'Suivi Client'!$C$2:$H$2000,2,FALSE)=0,"",VLOOKUP(I8,'Suivi Client'!$C$2:$H$2000,2,FALSE)) -> dan.acres@gmail.com
A16: numéro de facturation | C16: 58
A17: Date de facturation | C17: 45985
A21: Contenance | B21: Designation | H21: Qté | I21: Prix unitaire HT | K21: Montant HT
A23: =IF(VLOOKUP($C$16,'Suivi Facturation 2025'!$A$2:$M$1096,3,FALSE)>0,"0,75","") -> 0,75 | B23: =IF(VLOOKUP($C$16,'Suivi Facturation 2025'!$A$2:$M$978,3,FALSE)>0,"Bouteille CHAMPAGNE SELECTION","") -> Bouteille CHAMPAGNE SELECTION | H23: =IF(VLOOKUP($C$16,'Suivi Facturation 2025'!$A$2:$M$1096,3,FALSE)>0,VLOOKUP($C$16,'Suivi Facturation 2025'!$A$2:$M$1096,3,FALSE),"") -> 36 | I23: =IF(VLOOKUP($C$16,'Suivi Facturation 2025'!$A$2:$M$1096,3,FALSE)>0,'Suivi Facturation 2025'!S2,"") -> 17 | K23: =IF(VLOOKUP($C$16,'Suivi Facturation 2025'!$A$2:$M$1096,3,FALSE)>0,I23*H23,"") -> 612
A24: =IF(VLOOKUP($C$16,'Suivi Facturation 2025'!$A$2:$M$1096,4,FALSE)>0,"0,75","") | B24: =IF(VLOOKUP($C$16,'Suivi Facturation 2025'!$A$2:$M$978,4,FALSE)>0,"Bouteille CHAMPAGNE ROSE","") | H24: =IF(VLOOKUP($C$16,'Suivi Facturation 2025'!$A$2:$M$1096,4,FALSE)>0,VLOOKUP($C$16,'Suivi Facturation 2025'!$A$2:$M$1096,4,FALSE),"") | I24: =IF(VLOOKUP($C$16,'Suivi Facturation 2025'!$A$2:$M$1096,4,FALSE)>0,'Suivi Facturation 2025'!S3,"") | K24: =IF(VLOOKUP($C$16,'Suivi Facturation 2025'!$A$2:$M$1096,4,FALSE)>0,I24*H24,"")
A25: =IF(VLOOKUP($C$16,'Suivi Facturation 2025'!$A$2:$M$1096,5,FALSE)>0,"0,75","") | B25: =IF(VLOOKUP($C$16,'Suivi Facturation 2025'!$A$2:$M$978,5,FALSE)>0,"Bouteille CHAMPAGNE BLANC DE BLANC","") | H25: =IF(VLOOKUP($C$16,'Suivi Facturation 2025'!$A$2:$M$1996,5,FALSE)>0,VLOOKUP($C$16,'Suivi Facturation 2025'!$A$2:$M$1996,5,FALSE),"") | I25: =IF(VLOOKUP($C$16,'Suivi Facturation 2025'!$A$2:$M$1096,5,FALSE)>0,'Suivi Facturation 2025'!S4,"") | K25: =IF(VLOOKUP($C$16,'Suivi Facturation 2025'!$A$2:$M$1096,5,FALSE)>0,I25*H25,"")
A26: =IF(VLOOKUP($C$16,'Suivi Facturation 2025'!$A$2:$M$1096,6,FALSE)>0,"0,75","") | B26: =IF(VLOOKUP($C$16,'Suivi Facturation 2025'!$A$2:$M$1096,6,FALSE)>0,"Bouteille CHAMPAGNE PRESTIGE","") | H26: =IF(VLOOKUP($C$16,'Suivi Facturation 2025'!$A$2:$M$1096,6,FALSE)>0,VLOOKUP($C$16,'Suivi Facturation 2025'!$A$2:$M$1096,6,FALSE),"") | I26: =IF(VLOOKUP($C$16,'Suivi Facturation 2025'!$A$2:$M$1096,6,FALSE)>0,'Suivi Facturation 2025'!S5,"") | K26: =IF(VLOOKUP($C$16,'Suivi Facturation 2025'!$A$2:$M$1096,6,FALSE)>0,I26*H26,"")
A27: =IF(VLOOKUP($C$16,'Suivi Facturation 2025'!$A$2:$M$1096,7,FALSE)>0,"1,5","") | B27: =IF(VLOOKUP($C$16,'Suivi Facturation 2025'!$A$2:$M$1096,7,FALSE)>0,"MAGNUM SELECTION","") | I27: =IF(VLOOKUP($C$16,'Suivi Facturation 2025'!$A$2:$M$1096,7,FALSE)>0,'Suivi Facturation 2025'!S6,"") | K27: =IF(VLOOKUP($C$16,'Suivi Facturation 2025'!$A$2:$M$1096,7,FALSE)>0,I27*H27,"")
K40: Total HT | L40: =SUM(K23:L30) -> 612
A42: Toute somme impayée à son échéance produira, de plein droit et sans mise en demeure, un intérêt égal à 1,5 fois le taux d'intérêt légal par mois de retard. Nos conditions de vente ne prévoient pas d'escompte pour paiement anticipé. Coordonnées bancaires Titulaire du compte : JAMES CAROUGE IBAN FR76 1020 6000 4848 3510 3712 067 BIC AGRIFRPP802
A54: CHAMPAGNE CAROUGE CIREDDU 6 rue de l'eglise 51190 FLAVIGNY Tel : 06 77 95 90 62 SIRET 843 516 642 00017 N° TVA intracommunautaire FR67 843 516 642

Sheet Suivi Facturation 2024
A1: 4 | B1: Nom Client | C1: NB Selection | D1: NB Rosé | E1: Nb blanc de blan | F1: Nb Prestige | G1: Magnum Selection | I1: Montant TTC bouteilles | J1: Montant HT | K1: Date de facturation | L1: Etat paiement | M1: Etat Commande | N1: paiement | O1: commentaire | P1: Prix Transport TTC | R1: Statistiques | S1: Prix unitaire TTC | T1: =S2/1.2 -> 14.166667
A2: 1 | B2: JACKIE Guillaume | C2: 6 | I2: =IF(L2="Cadeau",0,C2*$S$2+D2*$S$3+E2*$S$4+F2*$S$5) -> 102 | J2: =I2/1.2 -> 85 | K2: 45326 | L2: REGLE | M2: Payé | R2: Sélection | S2: 17
A3: 2 | B3: SEVERINE PAQUIN | C3: 12 | E3: 12 | I3: =IF(L3="Cadeau",0,C3*$S$2+D3*$S$3+E3*$S$4+F3*$S$5) -> 426 | J3: =I3/1.2 -> 355 | K3: 45347 | L3: Payé | M3: Livrer | O3: CADEAU 1 ROSE | R3: Rosé | S3: 19
A4: 3 | B4: James Carouge | C4: 5 | E4: 3 | F4: 4 | I4: =IF(L4="Cadeau",0,C4*$S$2+D4*$S$3+E4*$S$4+F4*$S$5) -> 0 | J4: =I4/1.2 -> 0 | K4: 45349 | L4: Cadeau | O4: CONSO MAISON | R4: Blanc de blanc | S4: 18.5
A5: 4 | B5: CHRISTINE ABRY | C5: 24 | I5: =IF(L5="Cadeau",0,C5*$S$2+D5*$S$3+E5*$S$4+F5*$S$5) -> 408 | J5: =I5/1.2 -> 340 | K5: 45371 | L5: Payé | M5: Livrer | N5: LIVRAISON EN SUP | R5: Prestige | S5: 27
A6: 5 | B6: SARAH BLIN | E6: 48 | I6: =IF(L6="Cadeau",0,C6*$S$2+D6*$S$3+E6*$S$4+F6*$S$5) -> 888 | J6: =I6/1.2 -> 740 | K6: 45413 | L6: Payé | N6: GILLES PITOIS | P6: 120 | R6: Magnum Brut Selection | S6: 38
A7: 6 | B7: VICTOIRE SCHMITT | C7: 120 | I7: =IF(L7="Cadeau",0,C7*$S$2+D7*$S$3+E7*$S$4+F7*$S$5) -> 2040 | J7: =I7/1.2 -> 1700 | K7: 45425 | L7: Payé | M7: Livrer | N7: livraison 120 | R7: Nb bouteilles vendues | S7: =SUM(C2:D1201) -> 635
A8: 7 | I8: =IF(L8="Cadeau",0,C8*$S$2+D8*$S$3+E8*$S$4+F8*$S$5) -> 0 | J8: =I8/1.2 -> 0 | N8: CONSO MAISON
A9: 8 | B9: Philémon Parent | C9: 6 | I9: =IF(L9="Cadeau",0,C9*$S$2+D9*$S$3+E9*$S$4+F9*$S$5) -> 102 | J9: =I9/1.2 -> 85 | K9: 45435 | L9: Payé | M9: Livrer | N9: CHEQUE | R9: Chiffre d'affaire | S9: =SUM(I2:I1216) -> 17291
A10: 9 | B10: CHRITOPHE TRILLOT | C10: 96 | I10: =IF(L10="Cadeau",0,C10*$S$2+D10*$S$3+E10*$S$4+F10*$S$5) -> 1632 | J10: =I10/1.2 -> 1360 | K10: 45458 | L10: Payé | M10: Livrer | N10: MARIAGE | O10: cheque
A11: 10 | B11: Regis Paquin | E11: 18 | I11: =IF(L11="Cadeau",0,C11*$S$2+D11*$S$3+E11*$S$4+F11*$S$5) -> 333 | J11: =I11/1.2 -> 277.5 | K11: 45437 | L11: Payé | M11: Livrer | N11: VIREMENT
A12: 11 | B12: James Carouge | C12: 7 | E12: 3 | I12: =IF(L12="Cadeau",0,C12*$S$2+D12*$S$3+E12*$S$4+F12*$S$5) -> 0 | J12: =I12/1.2 -> 0 | K12: 45428 | L12: Cadeau | M12: Livrer | N12: CONSO CADEAU
A13: 12 | B13: James Carouge | L13: Cadeau | M13: Livrer | N13: CONSO
A14: 13 | B14: Gintrand Simon | E14: 18 | I14: =IF(L14="Cadeau",0,C14*$S$2+D14*$S$3+E14*$S$4+F14*$S$5) -> 333 | J14: =I14/1.2 -> 277.5 | K14: 45475 | L14: Payé | M14: Livrer | N14: VIREMENT
A15: 14 | B15: ISABELLE PASSA | C15: 18 | I15: =IF(L15="Cadeau",0,C15*$S$2+D15*$S$3+E15*$S$4+F15*$S$5) -> 306 | J15: =I15/1.2 -> 255 | K15: 45460 | L15: Payé | M15: Livrer | N15: LIVRAISON | O15: LIVRAISON 59,20 EN CHEQUE
A16: 15 | B16: Léo Carouge | E16: 6 | I16: =IF(L16="Cadeau",0,C16*$S$2+D16*$S$3+E16*$S$4+F16*$S$5) -> 0 | J16: =I16/1.2 -> 0 | K16: 45427 | L16: Cadeau | M16: Livrer
A17: 16 | B17: SCM MEDICALE INSTITUT DU SPO OLIVIER SELVA | E17: 36 | I17: =IF(L17="Cadeau",0,C17*$S$2+D17*$S$3+E17*$S$4+F17*$S$5) -> 666 | J17: =I17/1.2 -> 555 | K17: 45475 | L17: Payé | M17: Livrer | N17: VIREMENT
A18: 17 | B18: AGENCE LAGUILLON | E18: 60 | I18: =IF(L18="Cadeau",0,C18*$S$2+D18*$S$3+E18*$S$4+F18*$S$5) -> 1110 | J18: =I18/1.2 -> 925 | K18: 45490 | L18: Payé | M18: Livrer | N18: VIREMENT | O18: TRANSPORT GRATUIT
A19: 18 | B19: NICOLA CIREDDU | C19: 48 | F19: 6 | I19: =IF(L19="Cadeau",0,C19*$S$2+D19*$S$3+E19*$S$4+F19*$S$5) -> 978 | J19: =I19/1.2 -> 815 | K19: 45503 | L19: Payé | M19: Livrer | N19: ESPECE | O19: SARDAIGNE
A20: 19 | B20: Philippe Gintrand | C20: 30 | E20: 12 | I20: =IF(L20="Cadeau",0,C20*$S$2+D20*$S$3+E20*$S$4+F20*$S$5) -> 732 | J20: =I20/1.2 -> 610 | K20: 45495 | L20: Payé | M20: Livrer | N20: VIREMENT | O20: GIRARD 528 EUROS 12 BLC 18 SELEC
A21: 20 | B21: MARC LEFORT | C21: 6 | I21: =IF(L21="Cadeau",0,C21*$S$2+D21*$S$3+E21*$S$4+F21*$S$5) -> 102 | J21: =I21/1.2 -> 85 | K21: 45495 | L21: Payé | M21: Livrer | N21: VIREMENT | O21: ST VALLIER
A22: 21 | B22: PAOLA ZICCA | C22: 6 | E22: 12 | I22: =IF(L22="Cadeau",0,C22*$S$2+D22*$S$3+E22*$S$4+F22*$S$5) -> 324 | J22: =I22/1.2 -> 270 | K22: 45503 | L22: Payé | M22: Livrer | N22: ESPECE | O22: SARDAIGNE
A23: 22 | I23: =IF(L23="Cadeau",0,C23*$S$2+D23*$S$3+E23*$S$4+F23*$S$5) -> 0 | J23: =I23/1.2 -> 0 | K23: 45503 | L23: Payé | M23: Livrer | N23: ESPECE | O23: SARDAIGNE
A24: 23 | B24: James Carouge | D24: 6 | E24: 8 | F24: 6 | I24: =IF(L24="Cadeau",0,C24*$S$2+D24*$S$3+E24*$S$4+F24*$S$5) -> 0 | J24: =I24/1.2 -> 0 | K24: 45503 | L24: Cadeau | N24: CONSO SARDAIGNE | O24: SARDAIGNE
A25: 24 | B25: AIRBNB | I25: =IF(L25="Cadeau",0,C25*$S$2+D25*$S$3+E25*$S$4+F25*$S$5) -> 0 | J25: =I25/1.2 -> 0
A26: 25 | B26: cireddu camille | C26: 5 | I26: =IF(L26="Cadeau",0,C26*$S$2+D26*$S$3+E26*$S$4+F26*$S$5) -> 85 | J26: =I26/1.2 -> 70.833333 | K26: 45557 | L26: Payé | M26: Livrer | N26: FRANCESCA 3 BTL 51 VIREMT
A27: 26 | B27: Cadeau Vendages | C27: 4 | I27: =IF(L27="Cadeau",0,C27*$S$2+D27*$S$3+E27*$S$4+F27*$S$5) -> 0 | J27: =I27/1.2 -> 0 | K27: 45557 | L27: Cadeau | M27: Livrer | N27: VENDANGEURS
A28: 27 | B28: Sarha | C28: 2 | D28: 1 | I28: =IF(L28="Cadeau",0,C28*$S$2+D28*$S$3+E28*$S$4+F28*$S$5) -> 53 | J28: =I28/1.2 -> 44.166667 | K28: 45557 | L28: Payé | M28: Livrer | N28: VIREMENT
A29: 28 | B29: CHRISTINE ABRY | C29: 12 | I29: =IF(L29="Cadeau",0,C29*$S$2+D29*$S$3+E29*$S$4+F29*$S$5) -> 204 | J29: =I29/1.2 -> 170 | K29: 45582 | L29: Payé | M29: Livrer | N29: VIREMENT | O29: LIVRAISON
A30: 29 | B30: cireddu camille | C30: 6 | I30: =IF(L30="Cadeau",0,C30*$S$2+D30*$S$3+E30*$S$4+F30*$S$5) -> 102 | J30: =I30/1.2 -> 85 | K30: 45584 | L30: Payé | M30: Livrer | N30: 6 +2BTL FACT 25 VIREMT | O30: ENJY
A31: 30 | B31: James Carouge | C31: 1 | I31: =IF(L31="Cadeau",0,C31*$S$2+D31*$S$3+E31*$S$4+F31*$S$5) -> 0 | J31: =I31/1.2 -> 0 | K31: 45578 | L31: Cadeau | N31: CONSO
A32: 31 | B32: Stanislas BOUTMY | E32: 12 | I32: =IF(L32="Cadeau",0,C32*$S$2+D32*$S$3+E32*$S$4+F32*$S$5) -> 222 | J32: =I32/1.2 -> 185 | K32: 45592 | L32: A facturer | M32: Livrer
A33: 32 | B33: Stanislas BOUTMY | D33: 6 | E33: 6 | I33: =IF(L33="Cadeau",0,C33*$S$2+D33*$S$3+E33*$S$4+F33*$S$5) -> 225 | J33: =I33/1.2 -> 187.5 | K33: 45592 | L33: Payé | M33: Livrer | N33: VIREMENT
A34: 33 | B34: Bazin Etienne | E34: 6 | I34: =IF(L34="Cadeau",0,C34*$S$2+D34*$S$3+E34*$S$4+F34*$S$5) -> 111 | J34: =I34/1.2 -> 92.5 | K34: 45592 | L34: Payé | M34: Livrer | N34: VIREMENT
A35: 34 | B35: Léo Carouge | C35: 6 | E35: 6 | I35: =IF(L35="Cadeau",0,C35*$S$2+D35*$S$3+E35*$S$4+F35*$S$5) -> 0 | J35: =I35/1.2 -> 0 | K35: 45592 | L35: Cadeau | O35: CADEAU LEO
A36: 35 | B36: ZACHARIE Fassaert | C36: 10 | I36: =IF(L36="Cadeau",0,C36*$S$2+D36*$S$3+E36*$S$4+F36*$S$5) -> 170 | J36: =I36/1.2 -> 141.66667 | K36: 45601 | L36: Payé | N36: 2 CADEAU VIREMENT | O36: ANNIV ZAK
A37: 36 | B37: Nino Carouge | D37: 1 | F37: 2 | I37: =IF(L37="Cadeau",0,C37*$S$2+D37*$S$3+E37*$S$4+F37*$S$5) -> 0 | J37: =I37/1.2 -> 0 | K37: 45601 | L37: Cadeau | N37: DEGUSTATION | O37: ST JEAN DE LUZ
A38: 37 | B38: DANIEL ACRES | C38: 24 | I38: =IF(L38="Cadeau",0,C38*$S$2+D38*$S$3+E38*$S$4+F38*$S$5) -> 408 | J38: =I38/1.2 -> 340 | K38: 45613 | L38: Payé | M38: Livrer | N38: VIREMENT | O38: ITALIE HT
A39: 38 | B39: James Carouge | C39: 1 | D39: 1 | E39: 1 | F39: 1 | I39: =IF(L39="Cadeau",0,C39*$S$2+D39*$S$3+E39*$S$4+F39*$S$5) -> 0 | J39: =I39/1.2 -> 0 | K39: 45613 | L39: Cadeau | M39: Livrer | N39: SARDAIGNE CONSO
A40: 39 | B40: AIRBNB | C40: 1 | I40: =IF(L40="Cadeau",0,C40*$S$2+D40*$S$3+E40*$S$4+F40*$S$5) -> 0 | J40: =I40/1.2 -> 0 | K40: 45597 | L40: Cadeau | M40: Livrer
...

Sheet Facturation 2024
E5: CHAMPAGNE CAROUGE CIREDDU
G8: Nom | I8: =VLOOKUP(C16,'Suivi Facturation 2024'!$A$1:$K$10002,2,FALSE) -> Stanislas BOUTMY
G9: Adresse | I9: =VLOOKUP(I8,'Suivi Client'!C2:H2960,3,FALSE)
I10: =VLOOKUP(I8,'Suivi Client'!C2:H2960,4,FALSE) | J10: =VLOOKUP(I8,'Suivi Client'!C2:H2960,5,FALSE) -> PARIS
G12: Adresse e-mail | I12: =IF(VLOOKUP(I8,'Suivi Client'!$C$2:$H$2000,2,FALSE)=0,"",VLOOKUP(I8,'Suivi Client'!$C$2:$H$2000,2,FALSE)) -> stanislas.boutmy@sienna-im.com
M14: 23
A16: numéro de facturation | C16: 31
A17: Date de facturation
A21: Contenance | B21: Designation | H21: Qté | I21: Prix unitaire TTC | K21: Montant TTC
A23: =IF(VLOOKUP($C$16,'Suivi Facturation 2024'!$A$2:$M$1096,3,FALSE)>0,"0,75","") | B23: =IF(VLOOKUP($C$16,'Suivi Facturation 2024'!$A$2:$M$978,3,FALSE)>0,"Bouteille CHAMPAGNE SELECTION","") | H23: =IF(VLOOKUP($C$16,'Suivi Facturation 2025'!$A$2:$M$1096,3,FALSE)>0,VLOOKUP($C$16,'Suivi Facturation 2025'!$A$2:$M$1096,3,FALSE),"") | I23: =IF(VLOOKUP($C$16,'Suivi Facturation 2025'!$A$2:$M$1096,3,FALSE)>0,'Suivi Facturation 2025'!S2,"") | K23: =IF(VLOOKUP($C$16,'Suivi Facturation 2025'!$A$2:$M$1096,3,FALSE)>0,I23*H23,"")
A24: =IF(VLOOKUP($C$16,'Suivi Facturation 2024'!$A$2:$M$1096,4,FALSE)>0,"0,75","") | B24: =IF(VLOOKUP($C$16,'Suivi Facturation 2024'!$A$2:$M$978,4,FALSE)>0,"Bouteille CHAMPAGNE ROSE","") | H24: =IF(VLOOKUP($C$16,'Suivi Facturation 2025'!$A$2:$M$1096,4,FALSE)>0,VLOOKUP($C$16,'Suivi Facturation 2025'!$A$2:$M$1096,4,FALSE),"") | I24: =IF(VLOOKUP($C$16,'Suivi Facturation 2025'!$A$2:$M$1096,4,FALSE)>0,'Suivi Facturation 2025'!S3,"") | K24: =IF(VLOOKUP($C$16,'Suivi Facturation 2025'!$A$2:$M$1096,4,FALSE)>0,I24*H24,"")
A25: =IF(VLOOKUP($C$16,'Suivi Facturation 2024'!$A$2:$M$1096,5,FALSE)>0,"0,75","") -> 0,75 | B25: =IF(VLOOKUP($C$16,'Suivi Facturation 2024'!$A$2:$M$978,5,FALSE)>0,"Bouteille CHAMPAGNE BLANC DE BLANC","") -> Bouteille CHAMPAGNE BLANC DE BLANC | H25: =IF(VLOOKUP($C$16,'Suivi Facturation 2024'!$A$2:$M$1996,5,FALSE)>0,VLOOKUP($C$16,'Suivi Facturation 2024'!$A$2:$M$1996,5,FALSE),"") -> 12 | I25: =IF(VLOOKUP($C$16,'Suivi Facturation 2024'!$A$2:$M$1096,5,FALSE)>0,'Suivi Facturation 2024'!S4,"") -> 18.5 | K25: =IF(VLOOKUP($C$16,'Suivi Facturation 2024'!$A$2:$M$1096,5,FALSE)>0,I25*H25,"") -> 222
A26: =IF(VLOOKUP($C$16,'Suivi Facturation 2025'!$A$2:$M$1096,6,FALSE)>0,"0,75","") | B26: =IF(VLOOKUP($C$16,'Suivi Facturation 2025'!$A$2:$M$1096,6,FALSE)>0,"Bouteille CHAMPAGNE PRESTIGE","") | H26: =IF(VLOOKUP($C$16,'Suivi Facturation 2025'!$A$2:$M$1096,6,FALSE)>0,VLOOKUP($C$16,'Suivi Facturation 2025'!$A$2:$M$1096,6,FALSE),"") | I26: =IF(VLOOKUP($C$16,'Suivi Facturation 2025'!$A$2:$M$1096,6,FALSE)>0,'Suivi Facturation 2025'!S5,"") | K26: =IF(VLOOKUP($C$16,'Suivi Facturation 2025'!$A$2:$M$1096,6,FALSE)>0,I26*H26,"")
A27: =IF(VLOOKUP($C$16,'Suivi Facturation 2025'!$A$2:$M$1096,7,FALSE)>0,"1,5","") | B27: =IF(VLOOKUP($C$16,'Suivi Facturation 2025'!$A$2:$M$1096,7,FALSE)>0,"MAGNUM SELECTION","") | I27: =IF(VLOOKUP($C$16,'Suivi Facturation 2025'!$A$2:$M$1096,7,FALSE)>0,'Suivi Facturation 2025'!S6,"") | K27: =IF(VLOOKUP($C$16,'Suivi Facturation 2025'!$A$2:$M$1096,7,FALSE)>0,I27*H27,"")
B28: =IF(VLOOKUP($C$16,'Suivi Facturation 2025'!$A$2:$P$1978,16,FALSE)>0,"PRIX LIVRAISON","") | K28: =IF(VLOOKUP($C$16,'Suivi Facturation 2025'!$A$2:$P$1978,16,FALSE)>0,VLOOKUP($C$16,'Suivi Facturation 2025'!$A$2:$P$1978,16,FALSE),"")
K37: Total HT | L37: =SUM(K23:L30)-L38 -> 185
K38: TVA (20%) | L38: =IFERROR(SUM(K23:L29)-SUM(K23:L29)/1.2,"") -> 37
K40: Total TTC | L40: =SUM(K23:L30) -> 222
A42: Toute somme impayée à son échéance produira, de plein droit et sans mise en demeure, un intérêt égal à 1,5 fois le taux d'intérêt légal par mois de retard. Nos conditions de vente ne prévoient pas d'escompte pour paiement anticipé. Coordonnées bancaires Titulaire du compte : JAMES CAROUGE IBAN FR76 1020 6000 4848 3510 3712 067 BIC AGRIFRPP802
A54: CHAMPAGNE CAROUGE CIREDDU 6 rue de l'eglise 51190 FLAVIGNY Tel : 06 77 95 90 62 SIRET 843 516 642 00017 N° TVA intracommunautaire FR67 843 516 642

Sheet Facturation 2020
E5: CHAMPAGNE CAROUGE CIREDDU
G8: Nom | I8: =VLOOKUP(C16,'Suivi Facturation 2020'!$A$5:$I$10004,2,FALSE) -> #N/A
G9: Adresse | I9: =VLOOKUP(I8,'Suivi Client'!$C$2:$H$2000,3,FALSE) &" " & VLOOKUP(I8,'Suivi Client'!$C$2:$H$2000,4,FALSE) &" " & VLOOKUP(I8,'Suivi Client'!$C$2:$H$2000,5,FALSE) -> #N/A
G12: Adresse e-mail | I12: =IF(VLOOKUP(I8,'Suivi Client'!$C$2:$H$2000,2,FALSE)=0,"",VLOOKUP(I8,'Suivi Client'!$C$2:$H$2000,2,FALSE)) -> #N/A
A16: numéro de facturation | C16: 45
A17: Date de facturation
A21: Contenance | B21: Designation | H21: Qté | I21: Prix unitaire TTC | K21: Montant TTC
A23: =IF(VLOOKUP($C$16,'Suivi Facturation 2020'!$A$1:$I$104,3,FALSE)>0,"0,75","") -> #N/A | B23: =IF(VLOOKUP($C$16,'Suivi Facturation 2020'!$A$1:$I$104,3,FALSE)>0,"Bouteille CHAMPAGNE SELECTION","") -> #N/A | H23: =IF(VLOOKUP($C$16,'Suivi Facturation 2020'!$A$1:$I$104,3,FALSE)>0,VLOOKUP($C$16,'Suivi Facturation 2020'!$A$1:$I$104,3,FALSE),"") -> #N/A | I23: =IF(VLOOKUP($C$16,'Suivi Facturation 2020'!$A$1:$I$104,3,FALSE)>0,16,"") -> #N/A | K23: =IF(VLOOKUP($C$16,'Suivi Facturation 2020'!$A$1:$I$104,3,FALSE)>0,I23*H23,"") -> #N/A
A24: =IF(VLOOKUP($C$16,'Suivi Facturation 2020'!$A$1:$I$104,4,FALSE)>0,"0,75","") -> #N/A | B24: =IF(VLOOKUP($C$16,'Suivi Facturation 2020'!$A$1:$I$104,4,FALSE)>0,"Bouteille CHAMPAGNE ROSE","") -> #N/A | H24: =IF(VLOOKUP($C$16,'Suivi Facturation 2020'!$A$1:$I$104,4,FALSE)>0,VLOOKUP($C$16,'Suivi Facturation 2020'!$A$1:$I$104,4,FALSE),"") -> #N/A | I24: =IF(VLOOKUP($C$16,'Suivi Facturation 2020'!$A$1:$I$104,4,FALSE)>0,18,"") -> #N/A | K24: =IF(VLOOKUP($C$16,'Suivi Facturation 2020'!$A$1:$I$104,4,FALSE)>0,I24*H24,"") -> #N/A
K35: Total HT | L35: =SUM(K23:L24)-L36 -> #N/A
K36: TVA (20%) | L36: =IFERROR(SUM(K23:L24)-SUM(K23:L24)/1.2,"")
K38: Total TTC | L38: =SUM(K23:L24) -> #N/A
A40: Toute somme impayée à son échéance produira, de plein droit et sans mise en demeure, un intérêt égal à 1,5 fois le taux d'intérêt légal par mois de retard. Nos conditions de vente ne prévoient pas d'escompte pour paiement anticipé. Coordonnées bancaires Titulaire du compte : JAMES CAROUGE IBAN FR76 1020 6000 4848 3510 3712 067 BIC AGRIFRPP802
A52: CHAMPAGNE CAROUGE CIREDDU 6 rue de l'eglise 51190 FLAVIGNY Tel : 06 77 95 90 62 SIRET 843 516 642 00017 N° TVA intracommunautaire FR67 843 516 642

Sheet Facturation 2024 HT
E5: CHAMPAGNE CAROUGE CIREDDU
G8: Nom | I8: =VLOOKUP(C16,'Suivi Facturation 2025'!$A$1:$K$10002,2,FALSE) -> PAOLA ZICCA
G9: Adresse | I9: =VLOOKUP(I8,'Suivi Client'!C2:H2960,3,FALSE) -> VIA GIALETTO
I10: =VLOOKUP(I8,'Suivi Client'!C2:H2960,4,FALSE) -> 9100 | J10: =VLOOKUP(I8,'Suivi Client'!C2:H2960,5,FALSE) -> NUORO SARDEGNA
G12: Adresse e-mail | I12: =IF(VLOOKUP(I8,'Suivi Client'!$C$2:$H$2000,2,FALSE)=0,"",VLOOKUP(I8,'Suivi Client'!$C$2:$H$2000,2,FALSE))
A16: numéro de facturation | C16: 37
A17: Date de facturation | C17: 45613
A21: Contenance | B21: Designation | H21: Qté | I21: Prix unitaire HT | K21: Montant HT
A23: =IF(VLOOKUP($C$16,'Suivi Facturation 2025'!$A$2:$M$1096,3,FALSE)>0,"0,75","") -> 0,75 | B23: =IF(VLOOKUP($C$16,'Suivi Facturation 2025'!$A$2:$M$978,3,FALSE)>0,"Bouteille CHAMPAGNE SELECTION","") -> Bouteille CHAMPAGNE SELECTION | H23: =IF(VLOOKUP($C$16,'Suivi Facturation 2025'!$A$2:$M$1096,3,FALSE)>0,VLOOKUP($C$16,'Suivi Facturation 2025'!$A$2:$M$1096,3,FALSE),"") -> 6 | I23: =IF(VLOOKUP($C$16,'Suivi Facturation 2025'!$A$2:$M$1096,3,FALSE)>0,'Suivi Facturation 2025'!S2,"") -> 17 | K23: =IF(VLOOKUP($C$16,'Suivi Facturation 2025'!$A$2:$M$1096,3,FALSE)>0,I23*H23,"") -> 102
A24: =IF(VLOOKUP($C$16,'Suivi Facturation 2025'!$A$2:$M$1096,4,FALSE)>0,"0,75","") -> 0,75 | B24: =IF(VLOOKUP($C$16,'Suivi Facturation 2025'!$A$2:$M$978,4,FALSE)>0,"Bouteille CHAMPAGNE ROSE","") -> Bouteille CHAMPAGNE ROSE | H24: =IF(VLOOKUP($C$16,'Suivi Facturation 2025'!$A$2:$M$1096,4,FALSE)>0,VLOOKUP($C$16,'Suivi Facturation 2025'!$A$2:$M$1096,4,FALSE),"") -> 6 | I24: =IF(VLOOKUP($C$16,'Suivi Facturation 2025'!$A$2:$M$1096,4,FALSE)>0,'Suivi Facturation 2025'!S3,"") -> 19 | K24: =IF(VLOOKUP($C$16,'Suivi Facturation 2025'!$A$2:$M$1096,4,FALSE)>0,I24*H24,"") -> 114
A25: =IF(VLOOKUP($C$16,'Suivi Facturation 2025'!$A$2:$M$1096,5,FALSE)>0,"0,75","") -> 0,75 | B25: =IF(VLOOKUP($C$16,'Suivi Facturation 2025'!$A$2:$M$978,5,FALSE)>0,"Bouteille CHAMPAGNE BLANC DE BLANC","") -> Bouteille CHAMPAGNE BLANC DE BLANC | H25: =IF(VLOOKUP($C$16,'Suivi Facturation 2025'!$A$2:$M$1996,5,FALSE)>0,VLOOKUP($C$16,'Suivi Facturation 2025'!$A$2:$M$1996,5,FALSE),"") -> 24 | I25: =IF(VLOOKUP($C$16,'Suivi Facturation 2025'!$A$2:$M$1096,5,FALSE)>0,'Suivi Facturation 2025'!S4,"") -> 18.5 | K25: =IF(VLOOKUP($C$16,'Suivi Facturation 2025'!$A$2:$M$1096,5,FALSE)>0,I25*H25,"") -> 444
A26: =IF(VLOOKUP($C$16,'Suivi Facturation 2025'!$A$2:$M$1096,6,FALSE)>0,"0,75","") | B26: =IF(VLOOKUP($C$16,'Suivi Facturation 2025'!$A$2:$M$1096,6,FALSE)>0,"Bouteille CHAMPAGNE PRESTIGE","") | H26: =IF(VLOOKUP($C$16,'Suivi Facturation 2025'!$A$2:$M$1096,6,FALSE)>0,VLOOKUP($C$16,'Suivi Facturation 2025'!$A$2:$M$1096,6,FALSE),"") | I26: =IF(VLOOKUP($C$16,'Suivi Facturation 2025'!$A$2:$M$1096,6,FALSE)>0,'Suivi Facturation 2025'!S5,"") | K26: =IF(VLOOKUP($C$16,'Suivi Facturation 2025'!$A$2:$M$1096,6,FALSE)>0,I26*H26,"")
A27: =IF(VLOOKUP($C$16,'Suivi Facturation 2025'!$A$2:$M$1096,7,FALSE)>0,"1,5","") | B27: =IF(VLOOKUP($C$16,'Suivi Facturation 2025'!$A$2:$M$1096,7,FALSE)>0,"MAGNUM SELECTION","") | I27: =IF(VLOOKUP($C$16,'Suivi Facturation 2025'!$A$2:$M$1096,7,FALSE)>0,'Suivi Facturation 2025'!S6,"") | K27: =IF(VLOOKUP($C$16,'Suivi Facturation 2025'!$A$2:$M$1096,7,FALSE)>0,I27*H27,"")
B28: =IF(VLOOKUP($C$16,'Suivi Facturation 2025'!$A$2:$P$1978,14,FALSE)>0,"PRIX LIVRAISON","") -> PRIX LIVRAISON | K28: =IF(VLOOKUP($C$16,'Suivi Facturation 2025'!$A$2:$P$1978,14,FALSE)>0,VLOOKUP($C$16,'Suivi Facturation 2025'!$A$2:$P$1978,14,FALSE),"") -> ESPECE/ITALIE
K40: Total HT | L40: =SUM(K23:L30) -> 660
A42: Toute somme impayée à son échéance produira, de plein droit et sans mise en demeure, un intérêt égal à 1,5 fois le taux d'intérêt légal par mois de retard. Nos conditions de vente ne prévoient pas d'escompte pour paiement anticipé. Coordonnées bancaires Titulaire du compte : JAMES CAROUGE IBAN FR76 1020 6000 4848 3510 3712 067 BIC AGRIFRPP802
A54: CHAMPAGNE CAROUGE CIREDDU 6 rue de l'eglise 51190 FLAVIGNY Tel : 06 77 95 90 62 SIRET 843 516 642 00017 N° TVA intracommunautaire FR67 843 516 642

Sheet Suivi Facturation 2023
A1: N?8M | B1: Nom Client | C1: NB Selection | D1: NB Rosé | E1: Nb blanc de blan | F1: Nb Prestige | G1: Magnum Selection | I1: Montant TTC bouteilles | J1: Montant HT | K1: Date de facturation | L1: Etat paiement | M1: Etat Commande | N1: paiement | O1: commentaire | P1: Prix Transport TTC | R1: Statistiques | S1: Prix unitaire TTC | T1: =S2/1.2 -> 14.166667
A2: 1 | B2: Karine GATE | E2: 4 | I2: =IF(L2="Cadeau",0,C2*$S$2+D2*$S$3+E2*$S$4+F2*$S$5) -> 74 | J2: =I2/1.2 -> 61.666667 | K2: 44949 | L2: ATT | M2: En attente de paiement | O2: CAve Leo | P2: SORTIE EN DRM | R2: Sélection | S2: 17
A3: 2 | B3: Léo Carouge | C3: 12 | D3: 12 | I3: =IF(L3="Cadeau",0,C3*$S$2+D3*$S$3+E3*$S$4+F3*$S$5) -> 432 | J3: =I3/1.2 -> 360 | K3: 44964 | L3: En attente de paiement | M3: Livrer | R3: Rosé | S3: 19
A4: 3 | B4: LEO FISHER | E4: 6 | I4: =IF(L4="Cadeau",0,C4*$S$2+D4*$S$3+E4*$S$4+F4*$S$5) -> 111 | J4: =I4/1.2 -> 92.5 | K4: 44981 | L4: Payé | M4: Livrer | N4: VIREMENT 14/03 | O4: DEPOSER PAR NINO | R4: Blanc de blanc | S4: 18.5
A5: 4 | B5: HUGO LANDRIEU | C5: 6 | I5: =IF(L5="Cadeau",0,C5*$S$2+D5*$S$3+E5*$S$4+F5*$S$5) -> 102 | J5: =I5/1.2 -> 85 | K5: 44981 | L5: Payé | M5: Livrer | N5: VIREMENT 1 /03 | O5: DEPOSER PAR NINO | R5: Prestige | S5: 27
A6: 5 | B6: Regis Paquin | E6: 6 | I6: =IF(L6="Cadeau",0,C6*$S$2+D6*$S$3+E6*$S$4+F6*$S$5) -> 111 | J6: =I6/1.2 -> 92.5 | K6: 44985 | L6: Payé | M6: Livrer | N6: VIREMENT 1 OCTOBRE | R6: Magnum Brut Selection | S6: 38
A7: 6 | B7: ANNE KAES | C7: 3 | D7: 1 | I7: =IF(L7="Cadeau",0,C7*$S$2+D7*$S$3+E7*$S$4+F7*$S$5) -> 70 | J7: =I7/1.2 -> 58.333333 | K7: 44989 | L7: Payé | M7: Livrer | N7: 44992 | O7: DEPOT ISA 2021 | P7: SORTIE EN DRM | R7: Nb bouteilles vendues | S7: =SUM(C2:D1201) -> 552
A8: 7 | B8: James Carouge | C8: 1 | D8: 5 | E8: 5 | I8: =IF(L8="Cadeau",0,C8*$S$2+D8*$S$3+E8*$S$4+F8*$S$5) -> 0 | J8: =I8/1.2 -> 0 | K8: 45016 | L8: Cadeau | N8: CONSO SARDAIGNE
A9: 8 | B9: MARC WEBER | C9: 102 | I9: =IF(L9="Cadeau",0,C9*$S$2+D9*$S$3+E9*$S$4+F9*$S$5) -> 1734 | J9: =I9/1.2 -> 1445 | K9: 45040 | L9: Payé | M9: Habillé | N9: livraison 195,60 A leur frais 98 | P9: 98 | R9: Chiffre d'affaire | S9: =SUM(I2:I1216) -> 16457.5
A10: 9 | B10: SEVERINE PAQUIN | C10: 12 | E10: 18 | I10: =IF(L10="Cadeau",0,C10*$S$2+D10*$S$3+E10*$S$4+F10*$S$5) -> 537 | J10: =I10/1.2 -> 447.5 | K10: 45013 | L10: Payé | M10: Livrer | O10: H TAXE ERREUR
A11: 10 | B11: PAOLA ZICCA | C11: 18 | E11: 12 | I11: =IF(L11="Cadeau",0,C11*$S$2+D11*$S$3+E11*$S$4+F11*$S$5) -> 528 | J11: =I11/1.2 -> 440 | K11: 45016 | L11: Payé | M11: Livrer | N11: ESPECE | O11: SARDAIGNE
A12: 11 | B12: NICOLA CIREDDU | C12: 19 | D12: 10 | E12: 12 | F12: 13 | I12: =IF(L12="Cadeau",0,C12*$S$2+D12*$S$3+E12*$S$4+F12*$S$5) -> 1086 | J12: =I12/1.2 -> 905 | K12: 45016 | L12: Payé | M12: Livrer | N12: ESPECE | O12: CADEAU 1 ROSE
A13: 12 | I13: =IF(L13="Cadeau",0,C13*$S$2+D13*$S$3+E13*$S$4+F13*$S$5) -> 0 | J13: =I13/1.2 -> 0
A14: 13 | B14: ROBERTO ANEDDA | F14: 2 | I14: =IF(L14="Cadeau",0,C14*$S$2+D14*$S$3+E14*$S$4+F14*$S$5) -> 54 | J14: =I14/1.2 -> 45 | K14: 45016 | L14: Payé | N14: ESPECE | O14: SARDAIGNE
A15: 14 | I15: =IF(L15="Cadeau",0,C15*$S$2+D15*$S$3+E15*$S$4+F15*$S$5) -> 0 | J15: =I15/1.2 -> 0
A16: 15 | B16: ROBERTO ANEDDA | C16: 1 | D16: 1 | E16: 1 | F16: 1 | I16: =IF(L16="Cadeau",0,C16*$S$2+D16*$S$3+E16*$S$4+F16*$S$5) -> 81.5 | J16: =I16/1.2 -> 67.916667 | K16: 45016 | L16: Payé | N16: DEGUSTATION | O16: ATELIER DEL VINO
A17: 16 | B17: Philippe Gintrand | C17: 6 | D17: 6 | I17: =IF(L17="Cadeau",0,C17*$S$2+D17*$S$3+E17*$S$4+F17*$S$5) -> 216 | J17: =I17/1.2 -> 180 | K17: 45051 | L17: Payé | O17: SUR Depot st vallier
A18: 17 | B18: Tony Bocock | C18: 36 | E18: 6 | I18: =IF(L18="Cadeau",0,C18*$S$2+D18*$S$3+E18*$S$4+F18*$S$5) -> 723 | J18: =I18/1.2 -> 602.5 | K18: 45065 | L18: Payé | M18: Livrer | N18: VIREMENT | O18: REPRISE MAISON
A19: 18 | B19: James Carouge | C19: 4 | E19: 1 | I19: =IF(L19="Cadeau",0,C19*$S$2+D19*$S$3+E19*$S$4+F19*$S$5) -> 0 | J19: =I19/1.2 -> 0 | K19: 45065 | L19: Cadeau | N19: CADEAU ET DEGUSTATION | O19: 1 SEL SANS CRD
A20: 19 | B20: CLAUDE FORGET | C20: 6 | E20: 6 | I20: =IF(L20="Cadeau",0,C20*$S$2+D20*$S$3+E20*$S$4+F20*$S$5) -> 213 | J20: =I20/1.2 -> 177.5 | K20: 45066 | L20: Payé | M20: Livrer | N20: ESPECE | O20: AIRBNB
A21: 20 | B21: MARC WEBER | C21: 6 | I21: =IF(L21="Cadeau",0,C21*$S$2+D21*$S$3+E21*$S$4+F21*$S$5) -> 102 | J21: =I21/1.2 -> 85 | K21: 45068 | L21: Payé | M21: Livrer | N21: VIREMENT | P21: 19.06
A22: 21 | B22: Philippe Gintrand | D22: 9 | E22: 9 | I22: =IF(L22="Cadeau",0,C22*$S$2+D22*$S$3+E22*$S$4+F22*$S$5) -> 337.5 | J22: =I22/1.2 -> 281.25 | K22: 45091 | L22: Payé | M22: Livrer | N22: VIRT NEMO 225 | O22: DEPOT ST VALLIER
A23: 22 | B23: Léo Carouge | C23: 6 | E23: 12 | I23: =IF(L23="Cadeau",0,C23*$S$2+D23*$S$3+E23*$S$4+F23*$S$5) -> 324 | J23: =I23/1.2 -> 270 | K23: 45105 | L23: En attente de paiement | M23: Livrer
A24: 23 | B24: MARIA TERESA MASCARELLO | C24: 3 | E24: 2 | F24: 2 | I24: =IF(L24="Cadeau",0,C24*$S$2+D24*$S$3+E24*$S$4+F24*$S$5) -> 142 | J24: =I24/1.2 -> 118.33333 | K24: 45113 | L24: Payé | M24: Livrer | N24: ESPECE
A25: 24 | B25: THIBAULT DE SAINT PRIEST | E25: 36 | I25: =IF(L25="Cadeau",0,C25*$S$2+D25*$S$3+E25*$S$4+F25*$S$5) -> 666 | J25: =I25/1.2 -> 555 | K25: 45116 | L25: Payé | M25: Livrer | N25: VIREMENT | O25: PLUS LIVRAISQON | P25: 65.61
A26: 25 | B26: SEVERINE PAQUIN | E26: 6 | I26: =IF(L26="Cadeau",0,C26*$S$2+D26*$S$3+E26*$S$4+F26*$S$5) -> 111 | J26: =I26/1.2 -> 92.5 | K26: 45116 | L26: Payé | M26: Livrer | N26: VIREMENT 27/02 | O26: 1 ROSE CADEAUX
A27: 26 | B27: Gintrand Simon | E27: 48 | I27: =IF(L27="Cadeau",0,C27*$S$2+D27*$S$3+E27*$S$4+F27*$S$5) -> 888 | J27: =I27/1.2 -> 740 | K27: 45118 | L27: Payé | M27: Habillé | N27: VIREMENT | O27: 1 ROSE CADEAU
A28: 27 | B28: REMI PATIES | C28: 12 | E28: 6 | I28: =IF(L28="Cadeau",0,C28*$S$2+D28*$S$3+E28*$S$4+F28*$S$5) -> 315 | J28: =I28/1.2 -> 262.5 | K28: 45120 | L28: Payé | M28: Habillé | N28: 102 ESPESCE | O28: VIRT 213
A29: 28 | B29: ROBERTO ANEDDA | E29: 6 | F29: 6 | I29: =IF(L29="Cadeau",0,C29*$S$2+D29*$S$3+E29*$S$4+F29*$S$5) -> 273 | J29: =I29/1.2 -> 227.5 | K29: 45122 | L29: Payé | N29: virement le 17/01 | O29: SARDAIGNE
A30: 29 | B30: James Carouge | C30: 2 | E30: 2 | I30: =IF(L30="Cadeau",0,C30*$S$2+D30*$S$3+E30*$S$4+F30*$S$5) -> 0 | J30: =I30/1.2 -> 0 | K30: 45138 | L30: Cadeau | N30: 0 | O30: DEGUST | P30: SANS CRD
A31: 30 | B31: James Carouge | C31: 3 | D31: 2 | E31: 1 | I31: =IF(L31="Cadeau",0,C31*$S$2+D31*$S$3+E31*$S$4+F31*$S$5) -> 0 | J31: =I31/1.2 -> 0 | K31: 45138 | L31: Cadeau | N31: 0 | O31: CONSO | P31: AVEC CRD
A32: 31 | B32: James Carouge | C32: 6 | D32: 6 | E32: 6 | I32: =IF(L32="Cadeau",0,C32*$S$2+D32*$S$3+E32*$S$4+F32*$S$5) -> 0 | J32: =I32/1.2 -> 0 | K32: 45139 | L32: Cadeau | N32: sardaigne | O32: CONSO | P32: avec crd
A33: 32 | B33: Léo Carouge | E33: 1 | I33: =IF(L33="Cadeau",0,C33*$S$2+D33*$S$3+E33*$S$4+F33*$S$5) -> 0 | J33: =I33/1.2 -> 0 | K33: 45144 | L33: Cadeau | N33: DEGUSTATION
A34: 33 | B34: ROBERTO ANEDDA | C34: 12 | D34: 6 | E34: 6 | F34: 12 | I34: =IF(L34="Cadeau",0,C34*$S$2+D34*$S$3+E34*$S$4+F34*$S$5) -> 753 | J34: =I34/1.2 -> 627.5 | K34: 45148 | L34: Payé | M34: Livrer | N34: VIREMENT LE 17/01
A35: 34 | B35: James Carouge | C35: 6 | E35: 6 | I35: =IF(L35="Cadeau",0,C35*$S$2+D35*$S$3+E35*$S$4+F35*$S$5) -> 0 | J35: =I35/1.2 -> 0 | K35: 45148 | L35: Cadeau | N35: NOUS MEME
A36: 35 | B36: Stanislas BOUTMY | E36: 6 | I36: =IF(L36="Cadeau",0,C36*$S$2+D36*$S$3+E36*$S$4+F36*$S$5) -> 111 | J36: =I36/1.2 -> 92.5 | K36: 45170 | L36: Payé | M36: Livrer | N36: virement | O36: DEPOT LEO
A37: 36 | B37: Philémon Parent | C37: 6 | I37: =IF(L37="Cadeau",0,C37*$S$2+D37*$S$3+E37*$S$4+F37*$S$5) -> 102 | J37: =I37/1.2 -> 85 | K37: 45188 | L37: Payé | M37: Livrer | N37: CHEQUE | O37: GERMAINE
A38: 37 | B38: Cadeau Vendages | C38: 7 | E38: 1 | I38: =IF(L38="Cadeau",0,C38*$S$2+D38*$S$3+E38*$S$4+F38*$S$5) -> 0 | J38: =I38/1.2 -> 0 | K38: 45184 | L38: Cadeau | O38: VENDANGES
A39: 38 | B39: Regis Paquin | E39: 12 | I39: =IF(L39="Cadeau",0,C39*$S$2+D39*$S$3+E39*$S$4+F39*$S$5) -> 222 | J39: =I39/1.2 -> 185 | K39: 45199 | L39: Payé | N39: VIREMENT
A40: 39 | B40: LYDIA | E40: 2 | I40: =IF(L40="Cadeau",0,C40*$S$2+D40*$S$3+E40*$S$4+F40*$S$5) -> 37 | J40: =I40/1.2 -> 30.833333 | K40: 45078 | L40: Payé | N40: VIREMENT 40
...

Sheet Facturation 2023
E5: CHAMPAGNE CAROUGE CIREDDU
G8: Nom | I8: =VLOOKUP(C16,'Suivi Facturation 2023'!$A$1:$K$10002,2,FALSE) -> JOELLE DUBARBIER
G9: Adresse | I9: =VLOOKUP(I8,'Suivi Client'!C2:H2960,3,FALSE)
I10: =VLOOKUP(I8,'Suivi Client'!C2:H2960,4,FALSE) | J10: =VLOOKUP(I8,'Suivi Client'!C2:H2960,5,FALSE) -> SAINT JEAN DE LUZ
G12: Adresse e-mail | I12: =IF(VLOOKUP(I8,'Suivi Client'!$C$2:$H$2000,2,FALSE)=0,"",VLOOKUP(I8,'Suivi Client'!$C$2:$H$2000,2,FALSE))
M14: 23
A16: numéro de facturation | C16: 47
A17: Date de facturation | C17: 45260
A21: Contenance | B21: Designation | H21: Qté | I21: Prix unitaire TTC | K21: Montant TTC
A23: =IF(VLOOKUP($C$16,'Suivi Facturation 2023'!$A$2:$M$1096,3,FALSE)>0,"0,75","") | B23: =IF(VLOOKUP($C$16,'Suivi Facturation 2023'!$A$2:$M$978,3,FALSE)>0,"Bouteille CHAMPAGNE SELECTION","") | H23: =IF(VLOOKUP($C$16,'Suivi Facturation 2023'!$A$2:$M$1096,3,FALSE)>0,VLOOKUP($C$16,'Suivi Facturation 2023'!$A$2:$M$1096,3,FALSE),"") | I23: =IF(VLOOKUP($C$16,'Suivi Facturation 2023'!$A$2:$M$1096,3,FALSE)>0,'Suivi Facturation 2023'!S2,"") | K23: =IF(VLOOKUP($C$16,'Suivi Facturation 2023'!$A$2:$M$1096,3,FALSE)>0,I23*H23,"")
A24: =IF(VLOOKUP($C$16,'Suivi Facturation 2023'!$A$2:$M$1096,4,FALSE)>0,"0,75","") -> 0,75 | B24: =IF(VLOOKUP($C$16,'Suivi Facturation 2023'!$A$2:$M$978,4,FALSE)>0,"Bouteille CHAMPAGNE ROSE","") -> Bouteille CHAMPAGNE ROSE | H24: =IF(VLOOKUP($C$16,'Suivi Facturation 2023'!$A$2:$M$1096,4,FALSE)>0,VLOOKUP($C$16,'Suivi Facturation 2023'!$A$2:$M$1096,4,FALSE),"") -> 18 | I24: =IF(VLOOKUP($C$16,'Suivi Facturation 2023'!$A$2:$M$1096,4,FALSE)>0,'Suivi Facturation 2023'!S3,"") -> 19 | K24: =IF(VLOOKUP($C$16,'Suivi Facturation 2023'!$A$2:$M$1096,4,FALSE)>0,I24*H24,"") -> 342
A25: =IF(VLOOKUP($C$16,'Suivi Facturation 2023'!$A$2:$M$1096,5,FALSE)>0,"0,75","") -> 0,75 | B25: =IF(VLOOKUP($C$16,'Suivi Facturation 2023'!$A$2:$M$978,5,FALSE)>0,"Bouteille CHAMPAGNE BLANC DE BLANC","") -> Bouteille CHAMPAGNE BLANC DE BLANC | H25: =IF(VLOOKUP($C$16,'Suivi Facturation 2023'!$A$2:$M$1996,5,FALSE)>0,VLOOKUP($C$16,'Suivi Facturation 2023'!$A$2:$M$1996,5,FALSE),"") -> 18 | I25: =IF(VLOOKUP($C$16,'Suivi Facturation 2023'!$A$2:$M$1096,5,FALSE)>0,'Suivi Facturation 2023'!S4,"") -> 18.5 | K25: =IF(VLOOKUP($C$16,'Suivi Facturation 2023'!$A$2:$M$1096,5,FALSE)>0,I25*H25,"") -> 333
A26: =IF(VLOOKUP($C$16,'Suivi Facturation 2023'!$A$2:$M$1096,6,FALSE)>0,"0,75","") | B26: =IF(VLOOKUP($C$16,'Suivi Facturation 2023'!$A$2:$M$1096,6,FALSE)>0,"Bouteille CHAMPAGNE PRESTIGE","") | H26: =IF(VLOOKUP($C$16,'Suivi Facturation 2023'!$A$2:$M$1096,6,FALSE)>0,VLOOKUP($C$16,'Suivi Facturation 2023'!$A$2:$M$1096,6,FALSE),"") | I26: =IF(VLOOKUP($C$16,'Suivi Facturation 2023'!$A$2:$M$1096,6,FALSE)>0,'Suivi Facturation 2023'!S5,"") | K26: =IF(VLOOKUP($C$16,'Suivi Facturation 2023'!$A$2:$M$1096,6,FALSE)>0,I26*H26,"")
A27: =IF(VLOOKUP($C$16,'Suivi Facturation 2023'!$A$2:$M$1096,7,FALSE)>0,"1,5","") | B27: =IF(VLOOKUP($C$16,'Suivi Facturation 2023'!$A$2:$M$1096,7,FALSE)>0,"MAGNUM SELECTION","") | I27: =IF(VLOOKUP($C$16,'Suivi Facturation 2023'!$A$2:$M$1096,7,FALSE)>0,'Suivi Facturation 2023'!S6,"") | K27: =IF(VLOOKUP($C$16,'Suivi Facturation 2023'!$A$2:$M$1096,7,FALSE)>0,I27*H27,"")
B28: =IF(VLOOKUP($C$16,'Suivi Facturation 2023'!$A$2:$P$1978,16,FALSE)>0,"PRIX LIVRAISON","") -> PRIX LIVRAISON | K28: =IF(VLOOKUP($C$16,'Suivi Facturation 2023'!$A$2:$P$1978,16,FALSE)>0,VLOOKUP($C$16,'Suivi Facturation 2023'!$A$2:$P$1978,16,FALSE),"") -> 65
K37: Total HT | L37: =SUM(K23:L30)-L38 -> 616.66667
K38: TVA (20%) | L38: =IFERROR(SUM(K23:L29)-SUM(K23:L29)/1.2,"") -> 123.33333
K40: Total TTC | L40: =SUM(K23:L30) -> 740
A42: Toute somme impayée à son échéance produira, de plein droit et sans mise en demeure, un intérêt égal à 1,5 fois le taux d'intérêt légal par mois de retard. Nos conditions de vente ne prévoient pas d'escompte pour paiement anticipé. Coordonnées bancaires Titulaire du compte : JAMES CAROUGE IBAN FR76 1020 6000 4848 3510 3712 067 BIC AGRIFRPP802
A54: CHAMPAGNE CAROUGE CIREDDU 6 rue de l'eglise 51190 FLAVIGNY Tel : 06 77 95 90 62 SIRET 843 516 642 00017 N° TVA intracommunautaire FR67 843 516 642

Sheet Facturation 2023 HT
E5: CHAMPAGNE CAROUGE CIREDDU
G8: Nom | I8: =VLOOKUP(C16,'Suivi Facturation 2023'!$A$1:$K$10002,2,FALSE)
G9: Adresse | I9: =VLOOKUP(I8,'Suivi Client'!C2:H2960,3,FALSE) -> #N/A
I10: =VLOOKUP(I8,'Suivi Client'!C2:H2960,4,FALSE) -> #N/A | J10: =VLOOKUP(I8,'Suivi Client'!C2:H2960,5,FALSE) -> #N/A
G12: Adresse e-mail | I12: =IF(VLOOKUP(I8,'Suivi Client'!$C$2:$H$2000,2,FALSE)=0,"",VLOOKUP(I8,'Suivi Client'!$C$2:$H$2000,2,FALSE)) -> #N/A
A16: numéro de facturation | C16: 59
A17: Date de facturation | C17: 45613
A21: Contenance | B21: Designation | H21: Qté | I21: Prix unitaire HT | K21: Montant HT
A23: =IF(VLOOKUP($C$16,'Suivi Facturation 2023'!$A$2:$M$1096,3,FALSE)>0,"0,75","") | B23: =IF(VLOOKUP($C$16,'Suivi Facturation 2023'!$A$2:$M$978,3,FALSE)>0,"Bouteille CHAMPAGNE SELECTION","") | H23: =IF(VLOOKUP($C$16,'Suivi Facturation 2023'!$A$2:$M$1096,3,FALSE)>0,VLOOKUP($C$16,'Suivi Facturation 2023'!$A$2:$M$1096,3,FALSE),"") | I23: =IF(VLOOKUP($C$16,'Suivi Facturation 2023'!$A$2:$M$1096,3,FALSE)>0,'Suivi Facturation 2023'!S2,"") | K23: =IF(VLOOKUP($C$16,'Suivi Facturation 2023'!$A$2:$M$1096,3,FALSE)>0,I23*H23,"")
A24: =IF(VLOOKUP($C$16,'Suivi Facturation 2023'!$A$2:$M$1096,4,FALSE)>0,"0,75","") | B24: =IF(VLOOKUP($C$16,'Suivi Facturation 2023'!$A$2:$M$978,4,FALSE)>0,"Bouteille CHAMPAGNE ROSE","") | H24: =IF(VLOOKUP($C$16,'Suivi Facturation 2023'!$A$2:$M$1096,4,FALSE)>0,VLOOKUP($C$16,'Suivi Facturation 2023'!$A$2:$M$1096,4,FALSE),"") | I24: =IF(VLOOKUP($C$16,'Suivi Facturation 2023'!$A$2:$M$1096,4,FALSE)>0,'Suivi Facturation 2023'!S3,"") | K24: =IF(VLOOKUP($C$16,'Suivi Facturation 2023'!$A$2:$M$1096,4,FALSE)>0,I24*H24,"")
A25: =IF(VLOOKUP($C$16,'Suivi Facturation 2023'!$A$2:$M$1096,5,FALSE)>0,"0,75","") | B25: =IF(VLOOKUP($C$16,'Suivi Facturation 2023'!$A$2:$M$978,5,FALSE)>0,"Bouteille CHAMPAGNE BLANC DE BLANC","") | H25: =IF(VLOOKUP($C$16,'Suivi Facturation 2023'!$A$2:$M$1996,5,FALSE)>0,VLOOKUP($C$16,'Suivi Facturation 2023'!$A$2:$M$1996,5,FALSE),"") | I25: =IF(VLOOKUP($C$16,'Suivi Facturation 2023'!$A$2:$M$1096,5,FALSE)>0,'Suivi Facturation 2023'!S4,"") | K25: =IF(VLOOKUP($C$16,'Suivi Facturation 2023'!$A$2:$M$1096,5,FALSE)>0,I25*H25,"")
A26: =IF(VLOOKUP($C$16,'Suivi Facturation 2023'!$A$2:$M$1096,6,FALSE)>0,"0,75","") | B26: =IF(VLOOKUP($C$16,'Suivi Facturation 2023'!$A$2:$M$1096,6,FALSE)>0,"Bouteille CHAMPAGNE PRESTIGE","") | H26: =IF(VLOOKUP($C$16,'Suivi Facturation 2023'!$A$2:$M$1096,6,FALSE)>0,VLOOKUP($C$16,'Suivi Facturation 2023'!$A$2:$M$1096,6,FALSE),"") | I26: =IF(VLOOKUP($C$16,'Suivi Facturation 2023'!$A$2:$M$1096,6,FALSE)>0,'Suivi Facturation 2023'!S5,"") | K26: =IF(VLOOKUP($C$16,'Suivi Facturation 2023'!$A$2:$M$1096,6,FALSE)>0,I26*H26,"")
A27: =IF(VLOOKUP($C$16,'Suivi Facturation 2023'!$A$2:$M$1096,7,FALSE)>0,"1,5","") | B27: =IF(VLOOKUP($C$16,'Suivi Facturation 2023'!$A$2:$M$1096,7,FALSE)>0,"MAGNUM SELECTION","") | I27: =IF(VLOOKUP($C$16,'Suivi Facturation 2023'!$A$2:$M$1096,7,FALSE)>0,'Suivi Facturation 2023'!S6,"") | K27: =IF(VLOOKUP($C$16,'Suivi Facturation 2023'!$A$2:$M$1096,7,FALSE)>0,I27*H27,"")
B28: =IF(VLOOKUP($C$16,'Suivi Facturation 2023'!$A$2:$P$1978,14,FALSE)>0,"PRIX LIVRAISON","") | K28: =IF(VLOOKUP($C$16,'Suivi Facturation 2023'!$A$2:$P$1978,14,FALSE)>0,VLOOKUP($C$16,'Suivi Facturation 2023'!$A$2:$P$1978,14,FALSE),"")
K40: Total HT | L40: =SUM(K23:L30) -> 0
A42: Toute somme impayée à son échéance produira, de plein droit et sans mise en demeure, un intérêt égal à 1,5 fois le taux d'intérêt légal par mois de retard. Nos conditions de vente ne prévoient pas d'escompte pour paiement anticipé. Coordonnées bancaires Titulaire du compte : JAMES CAROUGE IBAN FR76 1020 6000 4848 3510 3712 067 BIC AGRIFRPP802
A54: CHAMPAGNE CAROUGE CIREDDU 6 rue de l'eglise 51190 FLAVIGNY Tel : 06 77 95 90 62 SIRET 843 516 642 00017 N° TVA intracommunautaire FR67 843 516 642

Sheet Suivi Facturation 2022
A1: 19/ | B1: Nom Client | C1: NB Selection | D1: NB Rosé | E1: Nb blanc de blan | F1: Nb Prestige | G1: Magnum Selection | I1: Montant TTC bouteilles | J1: Montant HT | K1: Date de facturation | L1: Etat paiement | M1: Etat Commande | N1: paiement | O1: commentaire | P1: Prix Transport TTC | R1: Statistiques | S1: Prix unitaire TTC | T1: =S2/1.2 -> 14.166667
A2: 1 | B2: CONSO | C2: 3 | D2: 1 | E2: 2 | F2: 3 | I2: =IF(L2="Cadeau",0,C2*$S$2+D2*$S$3+E2*$S$4+F2*$S$5) -> 0 | J2: =I2/1.2 -> 0 | K2: 44576 | L2: Cadeau | M2: Livrer | R2: Sélection | S2: 17
A3: 2 | B3: Gintrand Guillaume | E3: 18 | I3: =IF(L3="Cadeau",0,C3*$S$2+D3*$S$3+E3*$S$4+F3*$S$5) -> 333 | J3: =I3/1.2 -> 277.5 | K3: 44579 | L3: Payé | M3: Livrer | N3: VIREMENT 09/02 | O3: SAUVEGARDE EPERNAY | R3: Rosé | S3: 19
A4: 3 | B4: Philémon Parent | C4: 6 | E4: 2 | I4: =IF(L4="Cadeau",0,C4*$S$2+D4*$S$3+E4*$S$4+F4*$S$5) -> 139 | J4: =I4/1.2 -> 115.83333 | K4: 44696 | L4: Payé | M4: Habillé | N4: CHEQUE LE 05/07 | O4: LIVRE GERMAINE PAR JAMES | R4: Blanc de blanc | S4: 18.5
A5: 4 | B5: docteur RENZO MANFREDI | C5: 6 | E5: 12 | I5: =IF(L5="Cadeau",0,C5*$S$2+D5*$S$3+E5*$S$4+F5*$S$5) -> 324 | J5: =I5/1.2 -> 270 | K5: 44630 | L5: Payé | M5: Livrer | N5: CHEQUE LE 05/07 | O5: DEPOT REGIS | R5: Prestige | S5: 27
A6: 5 | B6: ZUPPING | C6: 4 | I6: =IF(L6="Cadeau",0,C6*$S$2+D6*$S$3+E6*$S$4+F6*$S$5) -> 68 | J6: =I6/1.2 -> 56.666667 | K6: 44578 | L6: Payé | M6: Livrer | N6: ZUPPING VIREMENT | O6: DEPOT DUBARBIER DEJA SORTIE EN DRM | R6: Magnum Brut Selection | S6: 38
A7: 6 | B7: SEJOURNE BASTIEN | C7: 1 | D7: 1 | E7: 3 | I7: =IF(L7="Cadeau",0,C7*$S$2+D7*$S$3+E7*$S$4+F7*$S$5) -> 91.5 | J7: =I7/1.2 -> 76.25 | K7: 44638 | L7: Payé | M7: Livrer | N7: VIREMENT | O7: REGLEE 21/11/2022 | R7: Nb bouteilles vendues | S7: =SUM(C2:D1201) -> 990
A8: =IF(L8="CAdeau",0,MAX($A$2:A7)+1) -> 7 | B8: DE MAUPEOU Thaîs | C8: 2 | I8: =IF(L8="Cadeau",0,C8*$S$2+D8*$S$3+E8*$S$4+F8*$S$5) -> 34 | J8: =I8/1.2 -> 28.333333 | K8: 44640 | L8: Payé | M8: Livrer | N8: VIREMENT | O8: SORTIE DEPOT LEO
A9: =IF(L9="CAdeau",0,MAX($A$2:A8)+1) -> 8 | B9: Locquet Jeremie | E9: 6 | I9: =IF(L9="Cadeau",0,C9*$S$2+D9*$S$3+E9*$S$4+F9*$S$5) -> 111 | J9: =I9/1.2 -> 92.5 | K9: 44639 | L9: Payé | M9: Livrer | N9: VIRE 10/2022 | O9: SORTIE DEPOT LEO | R9: Chiffre d'affaire | S9: =SUM(I2:I1216) -> 19625
A10: =IF(L10="CAdeau",0,MAX($A$2:A9)+1) -> 9 | B10: Eric Soulhac | D10: 3 | E10: 3 | I10: =IF(L10="Cadeau",0,C10*$S$2+D10*$S$3+E10*$S$4+F10*$S$5) -> 112.5 | J10: =I10/1.2 -> 93.75 | K10: 44643 | L10: Payé | M10: Livrer | N10: VIREMENT | O10: SORTIE DEPOT ST VALLIER | P10: PRIX 2021
A11: =IF(L11="CAdeau",0,MAX($A$2:A10)+1) -> 10 | B11: JAUNET CEDRIC | D11: 6 | E11: 6 | K11: 44654 | L11: Payé | M11: Livrer | N11: VIREMENT | O11: SORTIE MAISON
A12: =IF(L12="CAdeau",0,MAX($A$2:A11)+1) -> 11 | B12: Léo Carouge | C12: 12 | I12: =IF(L12="Cadeau",0,C12*$S$2+D12*$S$3+E12*$S$4+F12*$S$5) -> 204 | J12: =I12/1.2 -> 170 | K12: 44658 | L12: En attente de paiement | M12: Livrer | N12: LEO | O12: DEPOT LEO
A13: =IF(L13="CAdeau",0,MAX($A$2:A12)+1) -> 0 | B13: CONSO | C13: 2 | I13: =IF(L13="Cadeau",0,C13*$S$2+D13*$S$3+E13*$S$4+F13*$S$5) -> 0 | J13: =I13/1.2 -> 0 | K13: 44667 | L13: Cadeau | M13: Livrer | N13: 0 | O13: NINO
A14: =IF(L14="CAdeau",0,MAX($A$2:A13)+1) -> 12 | B14: DELFINI MARIE-SOPHIE | C14: 40 | I14: =IF(L14="Cadeau",0,C14*$S$2+D14*$S$3+E14*$S$4+F14*$S$5) -> 680 | J14: =I14/1.2 -> 566.66667 | K14: 44679 | L14: Payé | M14: Livrer | N14: Virement | O14: MARIAGE PARIS | P14: REMISE 1EURO BOUTEILLE
A15: =IF(L15="CAdeau",0,MAX($A$2:A14)+1) -> 13 | B15: ANNE KAES | C15: 6 | I15: =IF(L15="Cadeau",0,C15*$S$2+D15*$S$3+E15*$S$4+F15*$S$5) -> 102 | J15: =I15/1.2 -> 85 | K15: 44677 | L15: Payé | M15: Livrer | N15: VIREMENT | O15: SORTIE DEPOT ISA | P15: PRIX 2021
A16: =IF(L16="CAdeau",0,MAX($A$2:A15)+1) -> 14 | B16: Jac/dan Bouilot | C16: 18 | D16: 12 | I16: =IF(L16="Cadeau",0,C16*$S$2+D16*$S$3+E16*$S$4+F16*$S$5) -> 534 | J16: =I16/1.2 -> 445 | K16: 44698 | L16: Payé | M16: Livrer | N16: VIREMENT | O16: sortie depot st vallier | P16: prix 2021
